<?xml version="1.0"?>
<!--
Robot URDF/XACRO — Auto-generated by Hermod
@ai-context: This URDF describes the full kinematic tree of 巡检机器人-C3.
Type: diff_drive.
Link origins and joint axes are derived from robot.hardware.yaml.
Mass/inertia values are placeholders — replace with CAD-derived values.
@ai-extend: Add custom links, gazebo plugins, or transmission blocks below.
-->
<robot xmlns:xacro="http://www.ros.org/wiki/xacro" name="______C3">
<!-- ── Materials ── -->
<material name="base_grey">
<color rgba="0.3 0.3 0.3 1"/>
</material>
<material name="link_grey">
<color rgba="0.5 0.5 0.5 1"/>
</material>
<material name="sensor_blue">
<color rgba="0.2 0.4 0.8 1"/>
</material>

<!-- ═══════════════════════════════════════ -->
<!-- Base Link                               -->
<!-- ═══════════════════════════════════════ -->
<link name="base_link">
<inertial>
<mass value="3.0"/>
<inertia ixx="0.2" ixy="0" ixz="0" iyy="0.2" iyz="0" izz="0.2"/>
</inertial>
<visual>
<geometry>
<box size="0.4 0.25 0.15"/>
</geometry>
<material name="base_grey"/>
</visual>
<collision>
<geometry>
<box size="0.4 0.25 0.15"/>
</geometry>
</collision>
</link>

<!-- ═══════════════════════════════════════ -->
<!-- Mobile Base (Wheels)                    -->
<!-- ═══════════════════════════════════════ -->

<!-- Active: left_front_wheel (Motor: dji-m3508) -->
<link name="left_front_wheel">
<inertial>
<mass value="0.15"/>
<inertia ixx="0.0005" ixy="0" ixz="0" iyy="0.0005" iyz="0" izz="0.0005"/>
</inertial>
<visual>
<geometry><cylinder radius="0.06" length="0.03"/></geometry>
</visual>
</link>
<joint name="left_front_wheel_joint" type="continuous">
<parent link="base_link"/>
<child link="left_front_wheel"/>

<origin xyz="0 0.12 -0.05" rpy="0 0 0"/>

<axis xyz="0 1 0"/>
</joint>

<!-- Active: right_front_wheel (Motor: dji-m3508) -->
<link name="right_front_wheel">
<inertial>
<mass value="0.15"/>
<inertia ixx="0.0005" ixy="0" ixz="0" iyy="0.0005" iyz="0" izz="0.0005"/>
</inertial>
<visual>
<geometry><cylinder radius="0.06" length="0.03"/></geometry>
</visual>
</link>
<joint name="right_front_wheel_joint" type="continuous">
<parent link="base_link"/>
<child link="right_front_wheel"/>

<origin xyz="0 -0.12 -0.05" rpy="0 0 0"/>

<axis xyz="0 1 0"/>
</joint>

<!-- Active: left_rear_wheel (Motor: dji-m3508) -->
<link name="left_rear_wheel">
<inertial>
<mass value="0.15"/>
<inertia ixx="0.0005" ixy="0" ixz="0" iyy="0.0005" iyz="0" izz="0.0005"/>
</inertial>
<visual>
<geometry><cylinder radius="0.06" length="0.03"/></geometry>
</visual>
</link>
<joint name="left_rear_wheel_joint" type="continuous">
<parent link="base_link"/>
<child link="left_rear_wheel"/>

<origin xyz="0 0.12 -0.05" rpy="0 0 0"/>

<axis xyz="0 1 0"/>
</joint>

<!-- Active: right_rear_wheel (Motor: dji-m3508) -->
<link name="right_rear_wheel">
<inertial>
<mass value="0.15"/>
<inertia ixx="0.0005" ixy="0" ixz="0" iyy="0.0005" iyz="0" izz="0.0005"/>
</inertial>
<visual>
<geometry><cylinder radius="0.06" length="0.03"/></geometry>
</visual>
</link>
<joint name="right_rear_wheel_joint" type="continuous">
<parent link="base_link"/>
<child link="right_rear_wheel"/>

<origin xyz="0 -0.12 -0.05" rpy="0 0 0"/>

<axis xyz="0 1 0"/>
</joint>

<!-- ── Sensor Mounts ── -->

<link name="lidar_mount">
<inertial>
<mass value="0.01"/>
<inertia ixx="1e-6" ixy="0" ixz="0" iyy="1e-6" iyz="0" izz="1e-6"/>
</inertial>
<visual>
<geometry><box size="0.03 0.03 0.03"/></geometry>
<material name="sensor_blue"/>
</visual>
</link>
<joint name="lidar_joint" type="fixed">
<parent link="base_link"/>
<child link="lidar_mount"/>
<origin xyz="0.15 0 0.3"
rpy="0 0 0"/>
</joint>

<link name="imu_mount">
<inertial>
<mass value="0.01"/>
<inertia ixx="1e-6" ixy="0" ixz="0" iyy="1e-6" iyz="0" izz="1e-6"/>
</inertial>
<visual>
<geometry><box size="0.03 0.03 0.03"/></geometry>
<material name="sensor_blue"/>
</visual>
</link>
<joint name="imu_joint" type="fixed">
<parent link="base_link"/>
<child link="imu_mount"/>
<origin xyz="0 0 0.05"
rpy="0 0 0"/>
</joint>

<!-- ── @ai-extend: Add custom links and joints below ── -->
</robot>