<?xml version="1.0"?>
<!--
Robot URDF/XACRO — Auto-generated by Hermod
@ai-context: This URDF describes the full kinematic tree of 六轴协作机械臂.
Type: arm_6dof.
Link origins and joint axes are derived from robot.hardware.yaml.
Mass/inertia values are placeholders — replace with CAD-derived values.
@ai-extend: Add custom links, gazebo plugins, or transmission blocks below.
-->
<robot xmlns:xacro="http://www.ros.org/wiki/xacro" name="_______">
<!-- ── Materials ── -->
<material name="base_grey">
<color rgba="0.3 0.3 0.3 1"/>
</material>
<material name="link_grey">
<color rgba="0.5 0.5 0.5 1"/>
</material>
<material name="sensor_blue">
<color rgba="0.2 0.4 0.8 1"/>
</material>

<!-- ═══════════════════════════════════════ -->
<!-- Base Link                               -->
<!-- ═══════════════════════════════════════ -->
<link name="base_link">
<inertial>
<mass value="5.0"/>
<inertia ixx="0.5" ixy="0" ixz="0" iyy="0.5" iyz="0" izz="0.3"/>
</inertial>
<visual>
<geometry>
<box size="0.2 0.2 0.08"/>
</geometry>
<material name="base_grey"/>
</visual>
<collision>
<geometry>
<box size="0.2 0.2 0.08"/>
</geometry>
</collision>
</link>

<!-- ═══════════════════════════════════════ -->
<!-- Serial Chain (Manipulator Arm)          -->
<!-- ═══════════════════════════════════════ -->

<!-- Joint 1: joint_1_base (Motor: tmotor-ak80-9) -->
<link name="joint_1_base">
<inertial>
<mass value="1.5"/>
<inertia ixx="0.01" ixy="0" ixz="0" iyy="0.01" iyz="0" izz="0.005"/>
</inertial>
<visual>
<geometry>
<cylinder radius="0.05" length="0.25"/>
</geometry>
<material name="link_grey"/>
</visual>
<collision>
<geometry>
<cylinder radius="0.05" length="0.25"/>
</geometry>
</collision>
</link>
<joint name="joint_1_base_joint" type="revolute">
<parent link="base_link"/>
<child link="joint_1_base"/>
<origin xyz="0 0 0.3" rpy="0 0 0"/>
<axis xyz="0 0 1"/>
<limit effort="10"
velocity="6.283185307179585"
lower="-3.14"
upper="3.14"/>
</joint>

<!-- Joint 2: joint_2_shoulder (Motor: tmotor-ak80-9) -->
<link name="joint_2_shoulder">
<inertial>
<mass value="1.5"/>
<inertia ixx="0.01" ixy="0" ixz="0" iyy="0.01" iyz="0" izz="0.005"/>
</inertial>
<visual>
<geometry>
<cylinder radius="0.05" length="0.25"/>
</geometry>
<material name="link_grey"/>
</visual>
<collision>
<geometry>
<cylinder radius="0.05" length="0.25"/>
</geometry>
</collision>
</link>
<joint name="joint_2_shoulder_joint" type="revolute">
<parent link="joint_1_base"/>
<child link="joint_2_shoulder"/>
<origin xyz="0 0 0.3" rpy="0 0 0"/>
<axis xyz="0 1 0"/>
<limit effort="10"
velocity="6.283185307179585"
lower="-2"
upper="2"/>
</joint>

<!-- Joint 3: joint_3_elbow (Motor: tmotor-ak80-9) -->
<link name="joint_3_elbow">
<inertial>
<mass value="1.5"/>
<inertia ixx="0.01" ixy="0" ixz="0" iyy="0.01" iyz="0" izz="0.005"/>
</inertial>
<visual>
<geometry>
<cylinder radius="0.05" length="0.25"/>
</geometry>
<material name="link_grey"/>
</visual>
<collision>
<geometry>
<cylinder radius="0.05" length="0.25"/>
</geometry>
</collision>
</link>
<joint name="joint_3_elbow_joint" type="revolute">
<parent link="joint_2_shoulder"/>
<child link="joint_3_elbow"/>
<origin xyz="0 0 0.3" rpy="0 0 0"/>
<axis xyz="0 0 1"/>
<limit effort="10"
velocity="6.283185307179585"
lower="-2"
upper="2"/>
</joint>

<!-- Joint 4: joint_4_wrist_roll (Motor: dynamixel-xm430) -->
<link name="joint_4_wrist_roll">
<inertial>
<mass value="0.3"/>
<inertia ixx="0.01" ixy="0" ixz="0" iyy="0.01" iyz="0" izz="0.005"/>
</inertial>
<visual>
<geometry>
<cylinder radius="0.03" length="0.08"/>
</geometry>
<material name="link_grey"/>
</visual>
<collision>
<geometry>
<cylinder radius="0.03" length="0.08"/>
</geometry>
</collision>
</link>
<joint name="joint_4_wrist_roll_joint" type="revolute">
<parent link="joint_3_elbow"/>
<child link="joint_4_wrist_roll"/>
<origin xyz="0 0 0.15" rpy="0 0 0"/>
<axis xyz="0 1 0"/>
<limit effort="10"
velocity="6.283185307179585"
lower="-2"
upper="2"/>
</joint>

<!-- Joint 5: joint_5_wrist_pitch (Motor: dynamixel-xm430) -->
<link name="joint_5_wrist_pitch">
<inertial>
<mass value="0.3"/>
<inertia ixx="0.01" ixy="0" ixz="0" iyy="0.01" iyz="0" izz="0.005"/>
</inertial>
<visual>
<geometry>
<cylinder radius="0.03" length="0.08"/>
</geometry>
<material name="link_grey"/>
</visual>
<collision>
<geometry>
<cylinder radius="0.03" length="0.08"/>
</geometry>
</collision>
</link>
<joint name="joint_5_wrist_pitch_joint" type="revolute">
<parent link="joint_4_wrist_roll"/>
<child link="joint_5_wrist_pitch"/>
<origin xyz="0 0 0.15" rpy="0 0 0"/>
<axis xyz="0 0 1"/>
<limit effort="10"
velocity="6.283185307179585"
lower="-2"
upper="2"/>
</joint>

<!-- Joint 6: joint_6_wrist_yaw (Motor: dynamixel-xm430) -->
<link name="joint_6_wrist_yaw">
<inertial>
<mass value="0.3"/>
<inertia ixx="0.01" ixy="0" ixz="0" iyy="0.01" iyz="0" izz="0.005"/>
</inertial>
<visual>
<geometry>
<cylinder radius="0.03" length="0.08"/>
</geometry>
<material name="link_grey"/>
</visual>
<collision>
<geometry>
<cylinder radius="0.03" length="0.08"/>
</geometry>
</collision>
</link>
<joint name="joint_6_wrist_yaw_joint" type="revolute">
<parent link="joint_5_wrist_pitch"/>
<child link="joint_6_wrist_yaw"/>
<origin xyz="0 0 0.15" rpy="0 0 0"/>
<axis xyz="0 1 0"/>
<limit effort="10"
velocity="6.283185307179585"
lower="-2"
upper="2"/>
</joint>


<!-- ── Sensor Mounts ── -->

<link name="base_imu_mount">
<inertial>
<mass value="0.01"/>
<inertia ixx="1e-6" ixy="0" ixz="0" iyy="1e-6" iyz="0" izz="1e-6"/>
</inertial>
<visual>
<geometry><box size="0.03 0.03 0.03"/></geometry>
<material name="sensor_blue"/>
</visual>
</link>
<joint name="base_imu_joint" type="fixed">
<parent link="joint_1_base"/>
<child link="base_imu_mount"/>
<origin xyz="0 0 0.05"
rpy="0 0 0"/>
</joint>

<!-- ── @ai-extend: Add custom links and joints below ── -->
</robot>